<?xml version="1.0" encoding="utf-8"?>

<!-- RoboMaster 2024 英雄1号 -->
<robot name="rm_2024_HERO_1"
  xmlns:xacro="http://ros.org/wiki/xacro">

  <xacro:arg name="xyz" default="0.00 0 0.00" />
  <xacro:arg name="rpy" default="0 0 0" />

  <link name="odom" />
  <link name="gimbal_link" />
  <link name="gun_link" />
  <link name="camera_link" />
  <link name="camera_optical_frame" />

  <joint name="gimbal_joint" type="floating">
    <parent link="odom" />
    <child link="gimbal_link" />
  </joint>


  <joint name="gun_joint" type="fixed">
    <origin xyz="0.21 0 0" rpy="0 0 0" />
    <parent link="gimbal_link" />
    <child link="gun_link" />
  </joint>


  <joint name="camera_joint" type="fixed">
    <origin xyz="0.185 0.033 -0.052" rpy="${-1/180*pi} 0 0" />
    <parent link="gimbal_link" />
    <child link="camera_link" />
    <axis xyz="0 0 0" />
  </joint>


  <joint name="camera_optical_joint" type="fixed">
    <origin xyz="0 0 0" rpy="${-pi/2} 0 ${-pi/2}" />
    <parent link="camera_link" />
    <child link="camera_optical_frame" />
  </joint>

</robot>
